Workbook

Sheet СПиР
A2: Результаты оценки профессиональных знаний сотрудников Службы приема и размещения
A3: № п\п | B3: Объект | C3: Период тестирования | D3: Название теста | E3: Балл по тесту округлен без дробей | F3: Общий результат оценки по службе 2026 | G3: Общий результат оценки по службе 2025 | H3: Целевой показатель на 2026 год | I3: Отклонение результата прошлого года
A4: 1 | B4: Родина Гранд Отель и СПА Сочи | C4: 01.09.2026 - 01.10.2026 | D4: Тест для водителей | E4: 97 | F4: =AVERAGE(E4:E9) | G4: 85 | I4: =IF(N(G4)=0,"",F4-G4)
D5: Тест для консьержей | E5: 97
D6: Тест для начальника/заместителя начальника СПиО | E6: 91
D7: Тест для специалиста по взаимодействию с Гостями | E7: 95
D8: Тест для старшего консьержа | E8: 94
D9: Тест для телефонного оператора | E9: 95
A10: 2 | B10: Стандарт | C10: 01.09.2026 - 01.10.2026 | D10: Тестирование по СОП СПиР 2026 | E10: 97 | F10: =AVERAGE(E10:E11) | G10: 97 | I10: =IF(N(G10)=0,"",F10-G10)
D11: Тестирование по СОП СПиР (Беллманы) | E11: 80
A12: 3 | B12: Санаторий Валуево | C12: 01.09.2026 - 01.10.2026 | D12: Дежурный администратор 2026 | E12: 99 | F12: =AVERAGE(E12:E13) | G12: 98 | I12: =IF(N(G12)=0,"",F12-G12)
D13: Бронирование | E13: 100
A14: 4 | B14: Владивосток Гранд Отель и СПА | C14: 01.09.2026 - 01.10.2026 | D14: Тест Администратора СПиР | E14: 99 | F14: =AVERAGE(E14:E17) | G14: 84 | I14: =IF(N(G14)=0,"",F14-G14)
D15: Супервайзер СПиР | E15: 95
D16: Тест для Консьержа 2026 | E16: 100
D17: Тест для Посыльного 2026 | E17: 82
A18: 5 | B18: Гранд Отель Екатеринодар | C18: 01.09.2026 - 01.10.2026 | D18: Администратор СПиР. Часть 1-3 | E18: 99 | F18: =AVERAGE(E18:E18) | G18: 99 | I18: =IF(N(G18)=0,"",F18-G18)
A19: 6 | B19: Кызыл Гранд Отель и СПА | C19: 01.09.2026 - 01.10.2026 | D19: Оценка профессиональных знаний СГС ночной менеджер | E19: 70 | F19: =AVERAGE(E19:E20) | G19: 79 | I19: =IF(N(G19)=0,"",F19-G19)
D20: Оценка профессиональных знаний сотрудников СГС | E20: 75
A21: 7 | B21: Санаторий Родник | C21: 01.09.2026 - 01.10.2026 | D21: Тестирование администратора СПиР | E21: 96 | F21: =AVERAGE(E21:E21) | G21: 95 | I21: =IF(N(G21)=0,"",F21-G21)
A22: 8 | B22: Целеево | C22: 01.09.2026 - 01.10.2026 | D22: Оценка професссиональных знаний Администратора СПиР | E22: 98 | F22: =AVERAGE(E22:E23) | G22: 97 | I22: =IF(N(G22)=0,"",F22-G22)
D23: Бронирование номеров СПиР Целеево | E23: 98
A24: 9 | B24: RODINA Residences Vladivostok | C24: 01.09.2026 - 01.10.2026 | D24: Тест для ночного менеджера _ Ч 1-4 | E24: 94 | F24: =AVERAGE(E24:E25) | G24: 85 | I24: =IF(N(G24)=0,"",F24-G24)
D25: Тест для администратора _Ч1-4 | E25: 98
A26: 10 | B26: Родина Гранд Отель и СПА Иркутск | C26: 01.09.2026 - 01.10.2026 | D26: Тест для старшего администратора | E26: 97 | F26: =AVERAGE(E26:E28) | G26: 95 | I26: =IF(N(G26)=0,"",F26-G26)
D27: Тест для администратора | E27: 94
D28: Тест для ночного менеджера | E28: 99
A29: 11 | B29: Отель Sayen | C29: 01.09.2026 - 01.10.2026 | D29: Администратор | E29: 100 | F29: =AVERAGE(E29:E30) | G29: 0 | I29: =IF(N(G29)=0,"",F29-G29)
D30: Менеджер по работе с гостями | E30: 100
A31: 12 | B31: ДОЛ Дружба | C31: 01.09.2026 - 01.10.2026 | D31: тест Администратора | E31: 90 | F31: 90 | G31: 0 | I31: =IF(N(G31)=0,"",F31-G31)

Sheet СПиР_графики
A1: Рейтинг объектов по результатам оценки СПиР
A3: № | B3: Объект | C3: Фактический показатель | D3: Целевой показатель | E3: Отклонение от цели
A4: 1 | B4: Валуево | C4: =VLOOKUP(B4,СПиР!B$4:I$16,5,0) | D4: =VLOOKUP(B4,СПиР!B$4:I$16,6,0) | E4: =VLOOKUP(B4,СПиР!B$4:I$16,7,0)
A5: 2 | B5: Стандарт | C5: =VLOOKUP(B5,СПиР!B$4:I$16,5,0) | D5: =VLOOKUP(B5,СПиР!B$4:I$16,6,0) | E5: =VLOOKUP(B5,СПиР!B$4:I$16,7,0)
A6: 3 | B6: Имеретинский | C6: =VLOOKUP(B6,СПиР!B$4:I$16,5,0) | D6: =VLOOKUP(B6,СПиР!B$4:I$16,6,0) | E6: =VLOOKUP(B6,СПиР!B$4:I$16,7,0)
A7: 4 | B7: Родина | C7: =VLOOKUP(B7,СПиР!B$4:I$16,5,0) | D7: =VLOOKUP(B7,СПиР!B$4:I$16,6,0) | E7: =VLOOKUP(B7,СПиР!B$4:I$16,7,0)
A8: 5 | B8: Родник | C8: =VLOOKUP(B8,СПиР!B$4:I$16,5,0) | D8: =VLOOKUP(B8,СПиР!B$4:I$16,6,0) | E8: =VLOOKUP(B8,СПиР!B$4:I$16,7,0)
A9: 6 | B9: Сретенская | C9: =VLOOKUP(B9,СПиР!B$4:I$16,5,0) | D9: =VLOOKUP(B9,СПиР!B$4:I$16,6,0) | E9: =VLOOKUP(B9,СПиР!B$4:I$16,7,0)

Sheet Хоз.служба
A2: Результаты оценки профессиональных знаний сотрудников Хозяйственной службы
A3: № п\п | B3: Объект | C3: Период тестирования | D3: Название теста | E3: Балл по тесту округлен без дробей | F3: Общий результат оценки по службе 2026 | G3: Общий результат оценки по службе 2025 | H3: Целевой показатель на 2026 год | I3: Отклонение результата прошлого года
A4: 1 | B4: Родина Гранд Отель и СПА Сочи | C4: 01.09.2026 - 01.10.2026 | D4: Тест для горничной | E4: 98 | F4: =AVERAGE(E4:E9) | G4: 96 | I4: =IF(N(G4)=0,"",F4-G4)
D5: Тест для доставщика белья - рабочего | E5: 100
D6: Тест для сотрудников и руководителя прачечной | E6: 98
D7: Тест для супервайзера, заместителя начальника | E7: 93
D8: Тест для уборщика общественных помещений | E8: 98
D9: Тест для швеи | E9: 97
A10: 2 | B10: Стандарт | C10: 01.09.2026 - 01.10.2026 | D10: Тестирование по СОП СГХ 2026 | E10: 99 | F10: =AVERAGE(E10:E12) | G10: 97 | I10: =IF(N(G10)=0,"",F10-G10)
D11: Тестирование по СОП СГХ КМБ 2026 | E11: 96
D12: Тестирование по СОП 2026_Прачечная | E12: 99
A13: 3 | B13: Санаторий Валуево | C13: 01.09.2026 - 01.10.2026 | D13: Тест для горничных 2026 | E13: 96 | F13: =AVERAGE(E13:E14) | G13: 97 | I13: =IF(N(G13)=0,"",F13-G13)
D14: Тест по уборке коттеджей | E14: 97
A15: 4 | B15: Владивосток Гранд Отель и СПА | C15: 01.09.2026 - 01.10.2026 | D15: Горничные Часть 1-2 | E15: 85 | F15: =AVERAGE(E15:E22) | G15: 90.7 | I15: =IF(N(G15)=0,"",F15-G15)
D16: Супервайзер НФ. Часть 1 -2 | E16: 79
D17: Супервайзер ОЗ 2026 | E17: 79
D18: Тест для Оператора стиральных машин 2026 | E18: 97
D19: Тест для Супервайзера прачечной 2026 | E19: 89
D20: Тест для Швеи-униформиста 2026 | E20: 87
D21: Уборщик ОЗ 2026 | E21: 87
D22: Хаусмен 2026 | E22: 91
A23: 5 | B23: Главклинсервис | C23: 01.09.2026 - 01.10.2026 | D23: Уборщик производственных и санитарно-гигиенических помещений | E23: 97 | F23: 97 | G23: 94 | I23: =IF(N(G23)=0,"",F23-G23)
A24: 6 | B24: Гранд Отель Екатеринодар | C24: 01.09.2026 - 01.10.2026 | D24: Тест для супервайзеров. Часть 1-3 | E24: 93 | F24: =AVERAGE(E24:E25) | G24: 85 | I24: =IF(N(G24)=0,"",F24-G24)
D25: Тест для горничных. Часть 1-3 | E25: 94
A26: 7 | B26: Кызыл Гранд Отель и СПА | C26: 01.09.2026 - 01.10.2026 | D26: Оценка проф.знаний горничной | E26: 100 | F26: =AVERAGE(E26:E28) | G26: 73 | I26: =IF(N(G26)=0,"",F26-G26)
D27: Оценка проф.знаний Оператор Прачечной | E27: 100
D28: Оценка проф.знаний уборщицы общественных зон | E28: 91
A29: 8 | B29: Санаторий Родник | C29: 01.09.2026 - 01.10.2026 | D29: Тестирование супервайзеров, горничных | E29: 99 | F29: =AVERAGE(E29:E31) | G29: 97 | I29: =IF(N(G29)=0,"",F29-G29)
D30: Тест для горничной Клубный этаж | E30: 98.3
D31: Тест для супервайзера Клубный этаж | E31: 97
A32: 9 | B32: Целеево | C32: 01.09.2026 - 01.10.2026 | D32: Оценка профессиональных знаний по должности горничная | E32: 99 | F32: =AVERAGE(E32:E33) | G32: 99 | I32: =IF(N(G32)=0,"",F32-G32)
D33: Оценка профессиональных знаний по должности менеджера СХС | E33: 96
A34: 10 | B34: RODINA Residences Vladivostok | C34: 01.09.2026 - 01.10.2026 | D34: Тест для горничной | E34: 93 | F34: =AVERAGE(E34:E36) | G34: 90 | I34: =IF(N(G34)=0,"",F34-G34)
D35: Тест для Сотрудников прачечной+ швея кастелянша | E35: 96
D36: Тест для Супервайзера НФ Часть1-2 | E36: 88
A37: 11 | B37: Родина Гранд Отель и СПА Иркутск | C37: 01.09.2026 - 01.10.2026 | D37: Тест для супервайзера | E37: 97 | F37: =AVERAGE(E37:E41) | G37: 89 | H37: 85 | I37: =IF(N(G37)=0,"",F37-G37)
D38: Тест для горничной | E38: 98
D39: Тест хаусмен | E39: 97
D40: Тест для садовника | E40: 100
D41: Тест для оператора стиральных машин/ кастелянша-швея/технолог | E41: 99
...

Sheet F&B
A2: Результаты оценки профессиональных знаний сотрудников Службы питания
A3: № п\п | B3: Объект | C3: Период тестирования | D3: Название теста | E3: Балл по тесту округлен без дробей | F3: Общий результат оценки по службе 2026 | G3: Общий результат оценки по службе 2025 | H3: Целевой показатель на 2026 год | I3: Отклонение результата прошлого года
A4: 1 | B4: Родина Гранд Отель и СПА Сочи | C4: 01.09.2026 - 01.10.2026 | D4: Тест для администратора | E4: 97 | F4: =AVERAGE(E4:E17) | G4: 93 | I4: =IF(N(G4)=0,"",F4-G4)
D5: Тест для бармена | E5: 95
D6: Тест для официанта аля карт | E6: 95
D7: Тест для официанта шведки | E7: 96
D8: Тест для инженера-технолога Ч1-2 | E8: 100
D9: Тест для кондитера/пекаря | E9: 98.8
D10: Тест для старшего повара_повара | E10: 97
D11: Тест для Су-шефазаместителя шеф-повара Ч1-2 | E11: 98.7
D12: Тест для шеф-кондитера | E12: 99
D13: Тест по барному меню | E13: 95
D14: Тест по меню RODINA | E14: 96
D15: Тест по меню Москва | E15: 100
D16: Тест по меню рум-сервис | E16: 95
D17: Тест по меню ЧО-КО-ТЕ | E17: 92
A18: 2 | B18: Санаторий Валуево | C18: 01.09.2026 - 01.10.2026 | D18: Официант | E18: 91 | F18: =AVERAGE(E18:E20) | G18: 87 | I18: =IF(N(G18)=0,"",F18-G18)
D19: Повар | E19: 96
D20: Меню кафе Усадьба 2026 | E20: 96
A21: 3 | B21: Владивосток Гранд Отель и СПА | C21: 01.09.2026 - 01.10.2026 | D21: Тест для повара-заготовщика 2026 | E21: 94 | F21: =AVERAGE(E21:E35) | G21: 92 | I21: =IF(N(G21)=0,"",F21-G21)
D22: Тест для поваров Японского ресторана 2026 | E22: 55
D23: Ежегодная оценка Рум-сервис | E23: 87
D24: Тест для поваров 2026 | E24: 98
D25: Тест для стюарда 2026 | E25: 86
D26: Банкетная служба | E26: 84
D27: Бар Японского ресторана | E27: 80
D28: Детское меню | E28: 91
D29: Меню Японского ресторана | E29: 80
D30: Бар Японского ресторана | E30: 80
D31: Тест для бармена 2026 | E31: 93
D32: Меню Акватерра | E32: 91
D33: Тест для официанта и хостес, 2026 | E33: 83
... D35: Тест по вину и бару | E35: 97
B36: Ресторан Бенуар | C36: 01.09.2026 - 01.10.2026 | D36: Меню Бара | E36: 93 | F36: =AVERAGE(E36:E40) | G36: 98 | I36: =IF(N(G36)=0,"",F36-G36)
D37: Бармен | E37: 98
D38: Официант | E38: 98
D39: Хостес | E39: 100
D40: Основное меню Бенуар | E40: 100
A41: 4 | B41: Ресторан YURA | C41: 01.09.2026 - 01.10.2026 | D41: Бармен, Бар-Менеджер | E41: 93 | F41: =AVERAGE(E41:E49) | G41: 92 | I41: =IF(N(G41)=0,"",F41-G41)
D42: Барная и винная карта 2026 | E42: 97
...

Sheet F&B_графики
A2: Рейтинг объектов по результатам оценки СЛУЖБЫ ПИТАНИЯ
A3: № | B3: Объект | C3: Фактический показатель | D3: Целевой показатель | E3: Отклонение от цели
A4: 1 | B4: Имеретинский | C4: =VLOOKUP(B4,'F&B'!B4:I280,5,0) | D4: =VLOOKUP(B4,'F&B'!B4:I280,6,0) | E4: =VLOOKUP(B4,'F&B'!B4:I280,7,0)
A5: 2 | B5: Родина | C5: =VLOOKUP(B5,'F&B'!B4:I280,5,0) | D5: =VLOOKUP(B5,'F&B'!B4:I280,6,0) | E5: =VLOOKUP(B5,'F&B'!B4:I280,7,0)
A6: 3 | B6: Валуево | C6: =VLOOKUP(B6,'F&B'!B5:I281,5,0) | D6: =VLOOKUP(B6,'F&B'!B5:I281,6,0) | E6: =VLOOKUP(B6,'F&B'!B5:I281,7,0)
A7: 4 | B7: Сретенская | C7: =VLOOKUP(B7,'F&B'!B6:I282,5,0) | D7: =VLOOKUP(B7,'F&B'!B6:I282,6,0) | E7: =VLOOKUP(B7,'F&B'!B6:I282,7,0)
A8: 5 | B8: Родник | C8: =VLOOKUP(B8,'F&B'!B7:I283,5,0) | D8: =VLOOKUP(B8,'F&B'!B7:I283,6,0) | E8: =VLOOKUP(B8,'F&B'!B7:I283,7,0)
A9: 6 | B9: Кейтеринг Владивосток | C9: =VLOOKUP(B9,'F&B'!B7:I284,5,0) | D9: =VLOOKUP(B9,'F&B'!B7:I284,6,0) | E9: =VLOOKUP(B9,'F&B'!B7:I284,7,0)
A10: 7 | B10: YURA | C10: =VLOOKUP(B10,'F&B'!B8:I285,5,0) | D10: =VLOOKUP(B10,'F&B'!B8:I285,6,0) | E10: =VLOOKUP(B10,'F&B'!B8:I285,7,0)
A11: 8 | B11: Родина кейтеринг | C11: =VLOOKUP(B11,'F&B'!B9:I286,5,0) | D11: =VLOOKUP(B11,'F&B'!B9:I286,6,0) | E11: =VLOOKUP(B11,'F&B'!B9:I286,7,0)
A12: 9 | B12: ГлавПромПит | C12: =VLOOKUP(B12,'F&B'!B9:I287,5,0) | D12: =VLOOKUP(B12,'F&B'!B9:I287,6,0) | E12: =VLOOKUP(B12,'F&B'!B9:I287,7,0)

Sheet Хоз.служба_графики
A2: Рейтинг объектов по результатам оценки СГХ
A3: № | B3: Объект | C3: Фактический показатель | D3: Целевой показатель | E3: Отклонение от цели
A4: 1 | B4: Валуево | C4: =VLOOKUP(B4,Хоз.служба!B$4:I$25,5,0) | D4: =VLOOKUP(B4,Хоз.служба!B$4:I$25,6,0) | E4: =VLOOKUP($B4,Хоз.служба!$B$4:$I$25,7,0)
A5: 2 | B5: Имеретинский | C5: =VLOOKUP(B5,Хоз.служба!B$4:I$25,5,0) | D5: =VLOOKUP(B5,Хоз.служба!B$4:I$25,6,0) | E5: =VLOOKUP($B5,Хоз.служба!$B$4:$I$25,7,0)
A6: 3 | B6: Родина | C6: =VLOOKUP(B6,Хоз.служба!B$4:I$25,5,0) | D6: =VLOOKUP(B6,Хоз.служба!B$4:I$25,6,0) | E6: =VLOOKUP($B6,Хоз.служба!$B$4:$I$25,7,0)
A7: 4 | B7: Сретенская | C7: =VLOOKUP(B7,Хоз.служба!B$4:I$25,5,0) | D7: =VLOOKUP(B7,Хоз.служба!B$4:I$25,6,0) | E7: =VLOOKUP($B7,Хоз.служба!$B$4:$I$25,7,0)
A8: 5 | B8: Родник | C8: =VLOOKUP(B8,Хоз.служба!B$4:I$25,5,0) | D8: =VLOOKUP(B8,Хоз.служба!B$4:I$25,6,0) | E8: =VLOOKUP($B8,Хоз.служба!$B$4:$I$25,7,0)
A9: 6 | B9: Стандарт | C9: =VLOOKUP(B9,Хоз.служба!B$4:I$25,5,0) | D9: =VLOOKUP(B9,Хоз.служба!B$4:I$25,6,0) | E9: =VLOOKUP($B9,Хоз.служба!$B$4:$I$25,7,0)

Sheet Инженеры
A2: Результаты оценки профессиональных знаний сотрудников Инженерной службы
A3: № п\п | B3: Объект | C3: Период тестирования | D3: Название теста | E3: Балл по тесту округлен без дробей | F3: Общий результат оценки по службе 2026 | G3: Общий результат оценки по службе 2025 | H3: Целевой показатель на 2026 год | I3: Отклонение результата прошлого года
A4: 1 | B4: Родина Гранд Отель и СПА Сочи | C4: 01.09.2026 - 01.10.2026 | D4: Тест для диспетчера | E4: 100 | F4: =AVERAGE(E4:E12) | G4: 94 | I4: =IF(N(G4)=0,"",F4-G4)
D5: Тест для инженера зданий и сооружений | E5: 84
D6: Тест для инженера по эксплуатации систем водоснабжения, отопления, канализации | E6: 95
D7: Тест для инженера-теплотехника | E7: 65
D8: Тест для инженерного отдела | E8: 98
D9: Тест для оператора котельной | E9: 97
D10: Тест для слесаря-сантехника | E10: 98
D11: Тест для техника | E11: 97
D12: Тест для электромеханника | E12: 97
A13: 2 | B13: Стандарт | C13: 01.09.2026 - 01.10.2026 | D13: Тест СОП инженер-электрик | E13: 88 | F13: =AVERAGE(E13:E15) | G13: 93 | I13: =IF(N(G13)=0,"",F13-G13)
D14: Тест СОП плотник | E14: 100
D15: Тестирование по СОП 2026_ИТС | E15: 90
A16: 3 | B16: Санаторий Валуево | C16: 01.09.2026 - 01.10.2026 | D16: Маляр | E16: 82 | F16: =AVERAGE(E16:E20) | G16: 90 | I16: =IF(N(G16)=0,"",F16-G16)
D17: Оператор котельной | E17: 83
D18: Плотник | E18: 80
D19: Сантехник | E19: 85
D20: Электрик | E20: 82
A21: 4 | B21: Владивосток Гранд Отель и СПА | C21: 01.09.2026 - 01.10.2026 | D21: Администратор парковки 2026 | E21: 98 | F21: =AVERAGE(E21:E29) | G21: 96 | I21: =IF(N(G21)=0,"",F21-G21)
D22: Главный инженер, зам. главного инженера 2026. Ч 1-2 | E22: 98
D23: Главный энергетик 2026 | E23: 95
D24: Дежурный диспетчер 2026 | E24: 95
D25: Дежурный инженер 2026. Ч 1-2 | E25: 95
D26: Оператор слаботочных систем. Инженер по обслуживанию слабточных систем. Техник по СКУД 2026 | E26: 97
D27: Старший слесарь-сантехник. Слесарь-сантехник 2026 | E27: 99
D28: Старший электромеханик. Дежурный электрик. Электрик. Дежурный слесарь КИПиА 2026 | E28: 91
D29: Техник-отделочник. Отделочник-универсал. Плотник. Инженер ПГС 2026 | E29: 93
A30: 5 | B30: Кызыл Гранд Отель и СПА | C30: 01.09.2026 - 01.10.2026 | D30: Дежурный инженер | E30: 79 | F30: =AVERAGE(E30:E33) | G30: 69 | I30: =IF(N(G30)=0,"",F30-G30)
D31: Слесарь-сантехник | E31: 84
D32: Главный инженер | E32: 79
D33: Электрик | E33: 84
A34: 6 | B34: Санаторий Родник | C34: 01.09.2026 - 01.10.2026 | D34: Тестирование инженера по эксплуатации | E34: 96 | F34: =AVERAGE(E34:E37) | G34: 92.333333 | I34: =IF(N(G34)=0,"",F34-G34)
D35: Тестирование слесаря-электрика | E35: 90
D36: Тестирование сотрудников котельной | E36: 91
D37: Тестирование техника-универсала | E37: 88
A38: 7 | B38: Целеево | C38: 01.09.2026 - 01.10.2026 | D38: Дежурный электрик | E38: 97 | F38: =AVERAGE(E38:E44) | G38: 93 | I38: =IF(N(G38)=0,"",F38-G38)
D39: Инженер нкс | E39: 82
D40: Инженер по эксплуатации | E40: 98
D41: Машинист-оператор БКД | E41: 95
...

Sheet Инженеры_графики
A2: Рейтинг объектов по результатам оценки СГХ
A3: № | B3: Объект | C3: Фактический показатель | D3: Целевой показатель | E3: Отклонение от цели
A4: 1 | B4: Стандарт | C4: =VLOOKUP(B4,Инженеры!$B$4:$J$66,5,0) | D4: =VLOOKUP(B4,Инженеры!$B$4:$J$66,6,0) | E4: =VLOOKUP(B4,Инженеры!$B$4:$J$66,7,0)
A5: 2 | B5: Валуево | C5: =VLOOKUP(B5,Инженеры!$B$4:$J$66,5,0) | D5: =VLOOKUP(B5,Инженеры!$B$4:$J$66,6,0) | E5: =VLOOKUP(B5,Инженеры!$B$4:$J$66,7,0)
A6: 3 | B6: Родина | C6: =VLOOKUP(B6,Инженеры!$B$4:$J$66,5,0) | D6: =VLOOKUP(B6,Инженеры!$B$4:$J$66,6,0) | E6: =VLOOKUP(B6,Инженеры!$B$4:$J$66,7,0)
A7: 4 | B7: Родник | C7: =VLOOKUP(B7,Инженеры!$B$4:$J$66,5,0) | D7: =VLOOKUP(B7,Инженеры!$B$4:$J$66,6,0) | E7: =VLOOKUP(B7,Инженеры!$B$4:$J$66,7,0)
A8: 5 | B8: Сретенская | C8: =VLOOKUP(B8,Инженеры!$B$4:$J$66,5,0) | D8: =VLOOKUP(B8,Инженеры!$B$4:$J$66,6,0) | E8: =VLOOKUP(B8,Инженеры!$B$4:$J$66,7,0)
A9: 6 | B9: Имеретинский | C9: =VLOOKUP(B9,Инженеры!$B$4:$J$66,5,0) | D9: =VLOOKUP(B9,Инженеры!$B$4:$J$66,6,0) | E9: =VLOOKUP(B9,Инженеры!$B$4:$J$66,7,0)
A10: 7 | B10: ГКС | C10: =VLOOKUP(B10,Инженеры!$B$4:$J$66,5,0) | D10: =VLOOKUP(B10,Инженеры!$B$4:$J$66,6,0) | E10: =VLOOKUP(B10,Инженеры!$B$4:$J$66,7,0)

Sheet Бронирование
A2: Результаты оценки профессиональных знаний сотрудников Коммерческой службы (бронирование)
A3: № п\п | B3: № п\п | C3: Объект | D3: Период тестирования | E3: Название теста | F3: Балл по тесту округлен без дробей | G3: Общий результат оценки по службе 2026 | H3: Общий результат оценки по службе 2025 | I3: Целевой показатель на 2025 год | J3: Отклонение результата прошлого года
A4: 1 | B4: 1 | C4: Родина Гранд Отель и СПА Сочи | D4: 01.09.2026 - 01.10.2026 | E4: Тест по бронированию номеров Ч 1-2 | F4: 97 | G4: =AVERAGE(F4:F4) | H4: 95 | J4: =IF(N(H4)=0,"",G4-H4)
B5: 2 | C5: Санаторий Валуево | D5: 01.09.2026 - 01.10.2026 | E5: Тест медадминистратора | F5: 92 | G5: 92 | H5: 96 | J5: =IF(N(H5)=0,"",G5-H5)
A6: 2 | B6: 3 | C6: Стандарт | D6: 01.09.2026 - 01.10.2026 | E6: Тестирование по СОП ОБ 2026 | F6: 100 | G6: 100 | H6: 87 | J6: =IF(N(H6)=0,"",G6-H6)
A7: 4 | B7: 4 | C7: Владивосток Гранд Отель и СПА | D7: 01.09.2026 - 01.10.2026 | E7: Менеджер по бронированию | F7: 100 | G7: 100 | H7: 99 | J7: =IF(N(H7)=0,"",G7-H7)
A8: 5 | B8: 5 | C8: Санаторий Родник | D8: 01.09.2026 - 01.10.2026 | E8: Тестирование бронистов | F8: 95 | G8: =AVERAGE(F8:F9) | H8: 98 | J8: =IF(N(H8)=0,"",G8-H8)
E9: Тестирование по бронированию СМПиР | F9: 100
B10: 6 | C10: RODINA Residences Vladivostok | D10: 01.09.2026 - 01.10.2026 | E10: Тест Бронирование _ для сотрудников СПиР. Ч 1-2 | F10: 85 | G10: 85 | H10: 86 | J10: =IF(N(H10)=0,"",G10-H10)

Sheet СПА
A2: Результаты оценки профессиональных знаний сотрудников СПА
A3: № п\п | B3: Объект | C3: Период тестирования | D3: Название теста | E3: Балл по тесту округлен без дробей | F3: Общий результат оценки по службе 2026 | G3: Общий результат оценки по службе 2025 | H3: Целевой показатель на 2025 год | I3: Отклонение результата прошлого года
A4: 1 | B4: Родина Гранд Отель и СПА Сочи | C4: 01.09.2026 - 01.10.2026 | D4: Тест для администратора СПА | E4: 90.3 | F4: =AVERAGE(E4:E14) | G4: 88 | H4: 0 | I4: =IF(N(G4)=0,"",F4-G4)
D5: Тест для старшего матроса-спасателя | E5: 80
D6: Тест для спорт инструктора | E6: 100
D7: Тест для парикмахера стилиста | E7: 92
D8: Тест для мастера маникюра/педикюра | E8: 100
D9: Тест для врача невролога. Ч 1-2 | E9: 98
D10: Тест для главной медицинской сестры Ч 1-2 | E10: 100
D11: Тест для медицинской сестры по массажу Ч1-2 | E11: 92
D12: Тест для медицинской сестры по физиотерапии Ч1-2 | E12: 90
D13: Тест для медицинской сестры процедурной Ч1-2 | E13: 96
D14: Тест для фельдшера. Часть 1-2 | E14: 88
A15: 2 | B15: Владивосток Гранд Отель и СПА | C15: 01.09.2026 - 01.10.2026 | D15: Тест для массажиста, средней медицинской сестры, мастера ногтевого сервиса, парикмахера. 2026 | E15: 97 | F15: =AVERAGE(E15:E17) | G15: 94 | H15: 0 | I15: =IF(N(G15)=0,"",F15-G15)
D16: Тест для спасателя, фитнес-инструктора 2026 | E16: 98
D17: Тест. Администратор СПА. Ч 1-2. 2026 | E17: 99
A18: 3 | B18: Чистые пруды | C18: 01.09.2026 - 01.10.2026 | D18: Тестирование сотрудников подразделения медикал | E18: 90 | F18: =AVERAGE(E18:E19) | G18: 78 | H18: 0 | I18: =IF(N(G18)=0,"",F18-G18)
D19: Тестирование сотрудников подразделения сервис | E19: 96
A20: 4 | B20: Кызыл Гранд Отель и СПА | C20: 01.09.2026 - 01.10.2026 | D20: Оценка профессиональный знаний спасателя СПА | E20: 90 | F20: =AVERAGE(E20:E20) | G20: 88 | H20: 0 | I20: =IF(N(G20)=0,"",F20-G20)
A21: 5 | B21: Родина Гранд Отель и СПА Иркутск | C21: 01.09.2026 - 01.10.2026 | D21: Тест для администратора СПА | E21: 96.8 | F21: =AVERAGE(E21:E25) | G21: 93 | H21: 85 | I21: =IF(N(G21)=0,"",F21-G21)
D22: Тест для оператора СПА | E22: 98
D23: Тест для парильщика | E23: 92
D24: Тест для спасателя | E24: 99
D25: Тест для клинера | E25: 98
B26: Отель Sayen | C26: 01.09.2026 - 01.10.2026 | D26: Тестирование по СОП 2026: Старший массажист_массажист | E26: 98 | F26: =E26 | G26: 0 | H26: 85 | I26: =IF(N(G26)=0,"",F26-G26)
B53: Чистые П Раскладка
B54: Тест Администратора | C54: 91
B55: Сервис, Части 4: | C55: 96
C56: 98 | D56: =AVERAGE(C54:C58)
C57: 97
C58: 98
B60: врач-косметолог, 4 | C60: 63.6 | D60: =AVERAGE(C60:C63)
C61: 71
C62: 93
C63: 97
B65: массажист | C65: 98 | D65: =AVERAGE(C65:C69)
C66: 94
C67: 94
C68: 100
C69: 97
...

Sheet СПА_графики
A1: Рейтинг объектов по результатам оценки СПиР
A3: № | B3: Объект | C3: Фактический показатель | D3: Целевой показатель | E3: Отклонение от цели
A4: 1 | D4: =VLOOKUP(B4,СПиР!B$4:I$16,6,0) | E4: =VLOOKUP(B4,СПиР!B$4:I$16,7,0)
A5: 2 | D5: =VLOOKUP(B5,СПиР!B$4:I$16,6,0) | E5: =VLOOKUP(B5,СПиР!B$4:I$16,7,0)
A6: 3 | D6: =VLOOKUP(B6,СПиР!B$4:I$16,6,0) | E6: =VLOOKUP(B6,СПиР!B$4:I$16,7,0)
A7: 4 | D7: =VLOOKUP(B7,СПиР!B$4:I$16,6,0) | E7: =VLOOKUP(B7,СПиР!B$4:I$16,7,0)
A8: 5 | D8: =VLOOKUP(B8,СПиР!B$4:I$16,6,0) | E8: =VLOOKUP(B8,СПиР!B$4:I$16,7,0)
A9: 6 | D9: =VLOOKUP(B9,СПиР!B$4:I$16,6,0) | E9: =VLOOKUP(B9,СПиР!B$4:I$16,7,0)

Sheet Свод по службам
A1: Общая таблица результатов тестирования по службам
A3: № | B3: Объект | C3: Служба | D3: Фактический показатель | E3: Фактический показатель (Среднее по всем службам) | F3: Целевой показатель (Среднее по всем службам) | G3: Отклонение от цели (Среднее по всем службам) | H3: Комментарии | J3: Фактический показатель 2025 год (Среднее по всем службам) | K3: Изменение к 2025
A4: 1 | B4: RODINA Residences Vladivostok | C4: СПиР | D4: =IFERROR(VLOOKUP($B$4,'СПиР'!$B:$F,5,FALSE),"") | E4: =AVERAGE(D4:D7) | F4: 85 | G4: =E4-F4 | J4: 88.289583 | K4: =IF(N(J4)=0,"",E4-J4)
C5: Бронирование номеров | D5: =IFERROR(VLOOKUP($B$4,'Бронирование'!$C:$G,5,FALSE),"")
C6: Хозяйственная служба | D6: =IFERROR(VLOOKUP($B$4,'Хоз.служба'!$B:$F,5,FALSE),"")
C7: Инженерная служба | D7: =IFERROR(VLOOKUP($B$4,'Инженеры'!$B:$F,5,FALSE),"")
A8: 2 | B8: Владивосток Гранд Отель и СПА | C8: СПиР | D8: =IFERROR(VLOOKUP($B$8,'СПиР'!$B:$F,5,FALSE),"") | E8: =AVERAGE(D8:D13) | F8: 92 | G8: =E8-F8 | J8: 91.224282 | K8: =IF(N(J8)=0,"",E8-J8)
C9: Бронирование номеров | D9: =IFERROR(VLOOKUP($B$8,'Бронирование'!$C:$G,5,FALSE),"")
C10: Хозяйственная служба | D10: =IFERROR(VLOOKUP($B$8,'Хоз.служба'!$B:$F,5,FALSE),"")
C11: Служба питания | D11: =IFERROR(VLOOKUP($B$8,'F&B'!$B:$F,5,FALSE),"")
C12: Инженерная служба | D12: =IFERROR(VLOOKUP($B$8,'Инженеры'!$B:$F,5,FALSE),"")
C13: СПА | D13: =IFERROR(VLOOKUP($B$8,'СПА'!$B:$F,5,FALSE),"")
A14: 3 | B14: Ресторан Бенуар | C14: Служба питания | D14: =IFERROR(VLOOKUP($B$14,'F&B'!$B:$F,5,FALSE),"") | E14: =D14 | F14: 85 | G14: =E14-F14 | J14: 97.8 | K14: =IF(N(J14)=0,"",E14-J14)
A15: 4 | B15: Главклинсервис | C15: Хозяйственная служба (уборка) | D15: =IFERROR(VLOOKUP($B$15,'Хоз.служба'!$B:$F,5,FALSE),"") | E15: =AVERAGE(D15:D16) | F15: 89 | G15: =E15-F15 | J15: 95.333333 | K15: =IF(N(J15)=0,"",E15-J15)
C16: Инженерная служба | D16: =IFERROR(VLOOKUP($B$15,'Инженеры'!$B:$F,5,FALSE),"")
A17: 5 | B17: Гранд Отель Екатеринодар | C17: СПиР | D17: =IFERROR(VLOOKUP($B$17,'СПиР'!$B:$F,5,FALSE),"") | E17: =AVERAGE(D17:D20) | F17: 85 | G17: =E17-F17 | J17: 93.661111 | K17: =IF(N(J17)=0,"",E17-J17)
C18: Инженерная служба | D18: =IFERROR(VLOOKUP($B$17,'Инженеры'!$B:$F,5,FALSE),"")
C19: Хозяйственная служба | D19: =IFERROR(VLOOKUP($B$17,'Хоз.служба'!$B:$F,5,FALSE),"")
C20: Служба питания | D20: =IFERROR(VLOOKUP($B$17,'F&B'!$B:$F,5,FALSE),"")
A21: 6 | B21: Кейтеринг Владивосток | C21: Служба питания | D21: =IFERROR(VLOOKUP($B$21,'F&B'!$B:$F,5,FALSE),"") | E21: =AVERAGE(D21:D21) | F21: 85 | G21: =E21-F21 | J21: 94.857143 | K21: =IF(N(J21)=0,"",E21-J21)
A22: 7 | B22: Кызыл Гранд Отель и СПА | C22: СПиР | D22: =IFERROR(VLOOKUP($B$22,'СПиР'!$B:$F,5,FALSE),"") | E22: =AVERAGE(D22:D26) | F22: 85 | G22: =E22-F22 | J22: 77.261333 | K22: =IF(N(J22)=0,"",E22-J22)
C23: Хозяйственная служба | D23: =IFERROR(VLOOKUP($B$22,'Хоз.служба'!$B:$F,5,FALSE),"")
C24: Служба питания | D24: =IFERROR(VLOOKUP($B$22,'F&B'!$B:$F,5,FALSE),"")
C25: Инженерная служба | D25: =IFERROR(VLOOKUP($B$22,'Инженеры'!$B:$F,5,FALSE),"")
C26: СПА | D26: =IFERROR(VLOOKUP($B$22,'СПА'!$B:$F,5,FALSE),"")
A27: 8 | B27: Ресторан YURA | C27: Служба питания | D27: =IFERROR(VLOOKUP($B$27,'F&B'!$B:$F,5,FALSE),"") | E27: =AVERAGE(D27:D27) | F27: 90 | G27: =E27-F27 | J27: 92.233333 | K27: =IF(N(J27)=0,"",E27-J27)
A28: 9 | B28: Рестораны Тайгерс | C28: Служба питания | D28: =IFERROR(VLOOKUP($B$28,'F&B'!$B:$F,5,FALSE),"") | E28: =AVERAGE(D28:D28) | F28: 90 | G28: =E28-F28 | J28: 91.093333 | K28: =IF(N(J28)=0,"",E28-J28)
A29: 10 | B29: Родина Гранд Отель и СПА Сочи | C29: СПиР | D29: =IFERROR(VLOOKUP($B$29,'СПиР'!$B:$F,5,FALSE),"") | E29: =AVERAGE(D29:D34) | F29: 90 | G29: =E29-F29 | J29: 91.728023 | K29: =IF(N(J29)=0,"",E29-J29)
C30: Бронирование номеров | D30: =IFERROR(VLOOKUP($B$29,'Бронирование'!$C:$G,5,FALSE),"")
C31: Хозяйственная служба | D31: =IFERROR(VLOOKUP($B$29,'Хоз.служба'!$B:$F,5,FALSE),"")
C32: Служба питания | D32: =IFERROR(VLOOKUP($B$29,'F&B'!$B:$F,5,FALSE),"")
C33: Инженерная служба | D33: =IFERROR(VLOOKUP($B$29,'Инженеры'!$B:$F,5,FALSE),"")
C34: СПА | D34: =IFERROR(VLOOKUP($B$29,'СПА'!$B:$F,5,FALSE),"")
A35: 11 | B35: Родина кейтеринг | C35: Служба питания | D35: =IFERROR(VLOOKUP($B$35,'F&B'!$B:$F,5,FALSE),"") | E35: =AVERAGE(D35:D35) | F35: 91 | G35: =E35-F35 | J35: 88 | K35: =IF(N(J35)=0,"",E35-J35)
A36: 12 | B36: Санаторий Валуево | C36: СПиР | D36: =IFERROR(VLOOKUP($B$36,'СПиР'!$B:$F,5,FALSE),"") | E36: =AVERAGE(D36:D40) | F36: 95 | G36: =E36-F36 | J36: 93.666667 | K36: =IF(N(J36)=0,"",E36-J36)
C37: Бронирование номеров | D37: =IFERROR(VLOOKUP($B$36,'Бронирование'!$C:$G,5,FALSE),"")
C38: Хозяйственная служба | D38: =IFERROR(VLOOKUP($B$36,'Хоз.служба'!$B:$F,5,FALSE),"")
C39: Служба питания | D39: =IFERROR(VLOOKUP($B$36,'F&B'!$B:$F,5,FALSE),"")
C40: Инженерная служба | D40: =IFERROR(VLOOKUP($B$36,'Инженеры'!$B:$F,5,FALSE),"")
A41: 13 | B41: Санаторий Родник | C41: СПиР | D41: =IFERROR(VLOOKUP($B$41,'СПиР'!$B:$F,5,FALSE),"") | E41: =AVERAGE(D41:D45) | F41: 93 | G41: =E41-F41 | J41: 96.320952 | K41: =IF(N(J41)=0,"",E41-J41)
...

Sheet рабочий_данные СТАРЫЕ
A1: Служба | B1: Фактический показатель | C1: Объект
A2: СПиР | B2: 97.955 | C2: Санаторий Валуево
A3: Служба питания | B3: 81.466667
A4: Хозяйственная служба | B4: 98.296
A5: Коммерческая служба | B5: 75
A6: Инженеры | B6: 88.5325
A7: СПиР | B7: 89.938333 | C7: Родина Гранд Отель и СПА Сочи
A8: Служба питания | B8: 87.605
A9: Хозяйственная служба | B9: 95.685
A10: Коммерческая служба | B10: 56.5
A11: Инженеры | B11: 92.574545
A12: СПиР | B12: 83.69 | C12: Родник
A13: Служба питания | B13: 86.365
A14: Хозяйственная служба | B14: 99.37
A15: Коммерческая служба | B15: 70.83
A16: Инженеры | B16: 91.821667
A17: СПиР | B17: 98.4 | C17: Стандарт
A18: Хозяйственная служба | B18: 97.596667
A19: Коммерческая служба | B19: 61.975
A20: Инженеры | B20: 89.565714
A21: Служба питания | B21: 87.333333 | C21: Родина кейтеринг
A22: Служба питания | B22: 83.902222 | C22: Кейтеринг Владивосток
A23: Инженеры | B23: 88.727922 | C23: ГКС
A24: СПиР | B24: 95.38 | C24: Владивосток Гранд отель
A25: СПА | B25: 87.506
A26: Служба питания | B26: 79.313178
A27: Хозяйственная служба | B27: 90.860417
A28: Коммерческая служба | B28: 68.076667
A29: Инженеры | B29: 75.65
A30: СПиР | B30: 96.91 | C30: Целеево
A31: Служба питания | B31: 92.008
A32: Хозяйственная служба | B32: 97.715
A33: Коммерческая служба | B33: 61.79
A34: Инженеры | B34: нет результатов
A35: СПиР | B35: 77.593125 | C35: Кызыл Гранд Отель
A36: СПА | B36: 91.18
A37: Служба питания | B37: 77.289184
A38: Хозяйственная служба | B38: 87.573333
A39: Коммерческая служба | B39: 60
A40: Инженеры | B40: нет результатов
...
